# 异常情况详解

[异常机制](D:\个人文件\studyStore\java\异常机制(Throwable).xmind)

## 做以下情况区别：

### 1. catch中不包括的异常怎么办?

> 直接被抛出

### 2.catch 中再抛出异常,下面如果没有接受异常的怎么办?

>  会直接抛出，下面就算还有对应的catch语句，也还是抛出。除非再现有的整个代码上try..catch()..

```java
public class ExceptionTest {
    public static void main(String[] args) {
        try{
            try {
                File file=new File("");
                FileInputStream inputStream=new FileInputStream(file);
            }catch (FileNotFoundException e){
                System.out.println("捕获到FileNotFoundException");
                e.printStackTrace();
                int a=1/0;//被抛出

            }  finally{
                System.out.println("异常捕获结束 finally");
            }
        }catch (ArithmeticException e){//这样就能捕获了，不然直接被抛出
            System.out.println("又有一个异常被捕获了！");

        }

    }
}
```

### 3. 如果在try语句中有两处异常

```java
public class ExceptionTest {
    private String name="name";

    public static void main(String[] args) {
        ExceptionTest exceptionTest=null;
        try{
            System.out.println(exceptionTest.name);
            int a=1/0;//被抛出

        }
        catch (NullPointerException e) {
            System.out.println("捕获到NullPointerException");
            e.printStackTrace();
        }
        catch (Exception e){
            System.out.println("又有一个异常被捕获了！");
        }finally {
            System.out.println("异常捕获结束 finally");

        }

    }
}
```

>  这样也只会捕获到一个NullPointerException异常，Exception异常也不会被执行到的。

### 其他特点：

1. catch 不能捕获同一个异常
2. catch 后面的异常捕获，不能比上面的小。

